I'm sorry, but an uncaught exception occurred.

While running game code:
  File "game/script.rpy", line 467, in script
    dog "Yip!"
Exception: Sayer 'dog' is not defined.

-- Full Traceback ------------------------------------------------------------

Full traceback:
  File "game/script.rpy", line 467, in script
    dog "Yip!"
  File "C:\Users\Megan\Desktop\renpy-8.0.3-sdk\renpy\ast.py", line 881, in execute
    who = eval_who(self.who, self.who_fast)
  File "C:\Users\Megan\Desktop\renpy-8.0.3-sdk\renpy\ast.py", line 774, in eval_who
    raise Exception("Sayer '%s' is not defined." % who)
Exception: Sayer 'dog' is not defined.

Windows-10-10.0.22621 AMD64
Ren'Py 8.0.3.22090809
Voices From Beyond 1.0
Sun Mar 26 22:37:54 2023
